<?xml version="1.0" ?>
<!-- =================================================================================== -->
<!-- |    This document was autogenerated by xacro from isrobot.urdf                   | -->
<!-- |    EDITING THIS FILE BY HAND IS NOT RECOMMENDED                                 | -->
<!-- =================================================================================== -->
<robot name="isrobot">
  <link name="world"/>
  <joint name="base_joint" type="fixed">
    <origin rpy="0 0 0" xyz="0 0 0"/>
    <parent link="world"/>
    <child link="base_link"/>
  </joint>
  <link name="base_link">
    <visual>
      <origin rpy="0 0 0" xyz="0 0 0.13"/>
      <geometry>
        <box size="0.6 0.5 0.15"/>
      </geometry>
      <material name="base_material">
        <color rgba="1 1 1 1"/>
      </material>
    </visual>
    <collision>
      <origin rpy="0 0 0" xyz="0 0 0.13"/>
      <geometry>
        <box size="0.6 0.5 0.15"/>
      </geometry>
    </collision>
    <gazebo>
      <self_collide>true</self_collide>
      <enable_wind>true</enable_wind>
      <kinematic>false</kinematic>
      <material>Gazebo/Yellow</material>
      <!-- This is just an example, choose your own material -->
    </gazebo>
  </link>
  <joint name="base_frustum" type="fixed">
    <origin rpy="0 0 0" xyz="0 0 0"/>
    <parent link="base_link"/>
    <child link="frustum_link"/>
    <axis xyz="0 0 1"/>
  </joint>
  <!-- Frustum Link -->
  <link name="frustum_link">
    <!-- Visual Properties for the frustum (customize as needed) -->
    <visual>
      <origin rpy="0 0 0" xyz="0 0 0.505"/>
      <!-- Adjust the position -->
      <geometry>
        <mesh filename="package://hardware_interface_pkg/meshes/frustum.dae"/>
      </geometry>
      <material name="frustum_material">
        <color rgba="0 1 0 1"/>
        <!-- black color for the frustum -->
      </material>
    </visual>
    <!-- Collision Properties for the frustum (customize as needed) -->
    <collision>
      <geometry>
        <mesh filename="package://hardware_interface_pkg/meshes/frustum.dae"/>
      </geometry>
    </collision>
  </link>
  <joint name="frustum_cylinder" type="fixed">
    <origin rpy="0 0 0" xyz="0 0 0"/>
    <parent link="frustum_link"/>
    <child link="cylindrical_link"/>
    <axis xyz="0 0 1"/>
  </joint>
  <!-- Cylindrical Link -->
  <link name="cylindrical_link">
    <!-- Visual Properties for the cylindrical shape (customize as needed) -->
    <visual>
      <origin rpy="0 0 0" xyz="0 0 0.8353"/>
      <!-- Adjust the position -->
      <geometry>
        <cylinder length="0.0606" radius="0.075"/>
        <!-- Adjust dimensions for the cylinder -->
      </geometry>
      <material name="cylindrical_material">
        <color rgba="0 0 0 1"/>
        <!-- Red color for the cylindrical shape -->
      </material>
    </visual>
    <!-- Collision Properties for the cylindrical shape (customize as needed) -->
    <collision>
      <geometry>
        <cylinder length="0.0606" radius="0.15"/>
        <!-- Adjust dimensions for collision -->
      </geometry>
    </collision>
  </link>
  <joint name="cylindrical_midbody" type="fixed">
    <origin rpy="0 0 0" xyz="0 0 0"/>
    <parent link="cylindrical_link"/>
    <child link="midbody_link"/>
    <axis xyz="0 0 1"/>
  </joint>
  <!-- Spherical Link -->
  <link name="midbody_link">
    <!-- Visual Properties for the spherical shape (customize as needed) -->
    <visual>
      <origin rpy="0 0 0" xyz="0 0 0.8996"/>
      <!-- Adjust the position -->
      <geometry>
        <mesh filename="package://hardware_interface_pkg/meshes/midbody.dae"/>
      </geometry>
      <material name="spherical_material">
        <color rgba="0 0 0 1"/>
        <!-- Blue color for the spherical shape -->
      </material>
    </visual>
    <!-- Collision Properties for the spherical shape (customize as needed) -->
    <collision>
      <geometry>
        <mesh filename="package://hardware_interface_pkg/meshes/midbody.dae"/>
      </geometry>
    </collision>
  </link>
  <joint name="midbody_cuboidal" type="fixed">
    <origin rpy="0 0 0" xyz="0 0 0"/>
    <parent link="midbody_link"/>
    <child link="cuboidal_link"/>
    <axis xyz="0 0 1"/>
  </joint>
  <!-- Cuboidal Link -->
  <link name="cuboidal_link">
    <!-- Visual Properties for the cuboidal shape (customize as needed) -->
    <visual>
      <origin rpy="0 0 0" xyz="0 0 1.05"/>
      <!-- Adjust the position -->
      <geometry>
        <box size="0.12 0.05 0.268"/>
        <!-- Adjust dimensions for the cuboid -->
      </geometry>
      <material name="cuboidal_material">
        <color rgba="1 1 1 1"/>
        <!-- Yellow color for the cuboidal shape -->
      </material>
    </visual>
    <!-- Collision Properties for the cuboidal shape (customize as needed) -->
    <collision>
      <geometry>
        <box size="0.12 0.05 0.268"/>
        <!-- Adjust dimensions for collision -->
      </geometry>
    </collision>
  </link>
  <joint name="cuboidal_head" type="fixed">
    <origin rpy="0 0 0" xyz="0 0 0"/>
    <parent link="cuboidal_link"/>
    <child link="head_link"/>
    <axis xyz="0 0 1"/>
  </joint>
  <!-- Head Link (Add visual, collision, inertial, and joints as needed) -->
  <link name="head_link">
    <!-- Visual Properties for the cuboidal shape (customize as needed) -->
    <visual>
      <origin rpy="0 0 0" xyz="0 0 1.1666"/>
      <!-- Adjust the position -->
      <geometry>
        <box size="0.2184 0.09 0.15"/>
        <!-- Adjust dimensions for the cuboid -->
      </geometry>
      <material name="cuboidal_material">
        <color rgba="1 1 1 1"/>
        <!-- Yellow color for the cuboidal shape -->
      </material>
    </visual>
    <!-- Collision Properties for the cuboidal shape (customize as needed) -->
    <collision>
      <geometry>
        <box size="0.2184 0.09 0.15"/>
        <!-- Adjust dimensions for collision -->
      </geometry>
    </collision>
  </link>
  <joint name="head_display" type="fixed">
    <origin rpy="0 0 0" xyz="0 0 0"/>
    <parent link="head_link"/>
    <child link="display_link"/>
    <axis xyz="0 0 1"/>
  </joint>
  <!-- Head Link (Add visual, collision, inertial, and joints as needed) -->
  <link name="display_link">
    <!-- Visual Properties for the cuboidal shape (customize as needed) -->
    <visual>
      <origin rpy="0 0 0" xyz="0 0.03 1.1666"/>
      <!-- Adjust the position -->
      <geometry>
        <box size="0.2 0.07 0.1"/>
        <!-- Adjust dimensions for the cuboid -->
      </geometry>
      <material name="cuboidal_material">
        <color rgba="0 0 0 1"/>
        <!-- Yellow color for the cuboidal shape -->
      </material>
    </visual>
    <!-- Collision Properties for the cuboidal shape (customize as needed) -->
    <collision>
      <geometry>
        <box size="0.2 0.09 0.1"/>
        <!-- Adjust dimensions for collision -->
      </geometry>
    </collision>
  </link>
  <joint name="head_lidar" type="fixed">
    <origin rpy="0 0 0" xyz="0 0 0"/>
    <parent link="head_link"/>
    <child link="lidar_link"/>
    <axis xyz="0 0 1"/>
  </joint>
  <!-- Lidar Link -->
  <link name="lidar_link">
    <!-- Visual Properties for the lidar (customize as needed) -->
    <visual>
      <origin rpy="0 0 0" xyz="0 0 1.256"/>
      <geometry>
        <cylinder length="0.03" radius="0.035"/>
      </geometry>
      <material name="lidar_material">
        <color rgba="0 0 0 1"/>
        <!-- Red color for lidar -->
      </material>
    </visual>
    <!-- Collision Properties for the lidar (customize as needed) -->
    <collision>
      <geometry>
        <cylinder length="0.03" radius="0.035"/>
      </geometry>
    </collision>
  </link>
  <!-- Wheel Link -->
  <link name="wheel_link_1">
    <!-- Visual Properties for the wheel (customize as needed) -->
    <visual>
      <origin rpy="0 1.5 0" xyz="0.125 0.125 0.055"/>
      <geometry>
        <cylinder length="0.04" radius="0.07"/>
      </geometry>
      <material name="wheel_material">
        <color rgba="0 0 1 1"/>
        <!-- Black color for the wheel -->
      </material>
    </visual>
    <!-- Collision Properties for the wheel (customize as needed) -->
    <collision>
      <geometry>
        <cylinder length="0.04" radius="0.07"/>
      </geometry>
    </collision>
  </link>
  <!-- Wheel Link -->
  <link name="wheel_link_2">
    <!-- Visual Properties for the wheel (customize as needed) -->
    <visual>
      <origin rpy="0 1.5 0" xyz="-0.125 0.125 0.055"/>
      <geometry>
        <cylinder length="0.04" radius="0.07"/>
      </geometry>
      <material name="wheel_material">
        <color rgba="0 0 1 1"/>
        <!-- Black color for the wheel -->
      </material>
    </visual>
    <!-- Collision Properties for the wheel (customize as needed) -->
    <collision>
      <geometry>
        <cylinder length="0.04" radius="0.07"/>
      </geometry>
    </collision>
  </link>
  <!-- Wheel Link -->
  <link name="wheel_link_3">
    <!-- Visual Properties for the wheel (customize as needed) -->
    <visual>
      <origin rpy="0 1.5 0" xyz="-0.125 -0.125 0.055"/>
      <geometry>
        <cylinder length="0.04" radius="0.07"/>
      </geometry>
      <material name="wheel_material">
        <color rgba="0 0 1 1"/>
        <!-- Black color for the wheel -->
      </material>
    </visual>
    <!-- Collision Properties for the wheel (customize as needed) -->
    <collision>
      <geometry>
        <cylinder length="0.04" radius="0.07"/>
      </geometry>
    </collision>
  </link>
  <!-- Wheel Link -->
  <link name="wheel_link_4">
    <!-- Visual Properties for the wheel (customize as needed) -->
    <visual>
      <origin rpy="0 1.5 0" xyz="0.125 -0.125 0.055"/>
      <geometry>
        <cylinder length="0.04" radius="0.07"/>
      </geometry>
      <material name="wheel_material">
        <color rgba="0 0 1 1"/>
        <!-- Black color for the wheel -->
      </material>
    </visual>
    <!-- Collision Properties for the wheel (customize as needed) -->
    <collision>
      <geometry>
        <cylinder length="0.04" radius="0.07"/>
      </geometry>
    </collision>
  </link>
  <!-- Attach the wheels to the base link using joints -->
  <joint name="wheel_joint_1" type="continuous">
    <origin rpy="0 0 0" xyz="0 0 0"/>
    <parent link="base_link"/>
    <child link="wheel_link_1"/>
    <axis xyz="0 1 0"/>
  </joint>
  <joint name="wheel_joint_2" type="continuous">
    <origin rpy="0 0 0" xyz="0 0 0"/>
    <parent link="base_link"/>
    <child link="wheel_link_2"/>
    <axis xyz="0 1 0"/>
  </joint>
  <joint name="wheel_joint_3" type="continuous">
    <origin rpy="0 0 0" xyz="0 0 0"/>
    <parent link="base_link"/>
    <child link="wheel_link_3"/>
    <axis xyz="0 1 0"/>
  </joint>
  <joint name="wheel_joint_4" type="continuous">
    <origin rpy="0 0 0" xyz="0 0 0"/>
    <parent link="base_link"/>
    <child link="wheel_link_4"/>
    <axis xyz="0 1 0"/>
  </joint>
  <!-- Camera Sensor -->
  <gazebo reference="head_link">
    <sensor name="head_camera" type="camera">
      <camera name="head_camera">
        <!-- Camera parameters -->
        <horizontal_fov>1.047</horizontal_fov>
        <image>
          <width>640</width>
          <height>480</height>
          <format>R8G8B8</format>
        </image>
        <clip>
          <near>0.01</near>
          <far>100</far>
        </clip>
        <noise>
          <type>gaussian</type>
          <!-- Noise is sampled independently per pixel on each frame.
               That pixel's noise value is added to each of its color
               channels, which at that point lie in the range [0,1]. -->
          <mean>0.0</mean>
          <stddev>0.007</stddev>
        </noise>
      </camera>
      <!-- Add a plugin to specify the ROS topic name -->
      <plugin filename="libgazebo_ros_camera.so" name="camera_controller">
        <!-- Sensor settings -->
        <always_on>true</always_on>
        <update_rate>30.0</update_rate>
        <visualize>true</visualize>
        <cameraName>isrobot/front_cam</cameraName>
        <imageTopicName>image_raw</imageTopicName>
        <cameraInfoTopicName>camera_info</cameraInfoTopicName>
        <frameName>camera_link</frameName>
        <hackBaseline>0.07</hackBaseline>
        <distortionK1>0.0</distortionK1>
        <distortionK2>0.0</distortionK2>
        <distortionK3>0.0</distortionK3>
        <distortionT1>0.0</distortionT1>
        <distortionT2>0.0</distortionT2>
      </plugin>
    </sensor>
  </gazebo>
</robot>

